Workbook

Sheet customers_clean
A1: customer_id | B1: customer_name | C1: email | D1: phone | E1: country | F1: signup_date
A2: 770487 | B2: Joseph Brown | C2: joseph.brown760@example.com | D2: 428-342-2679 | E2: Spain | F2: 45063
A3: 809570 | B3: Helen Lopez | C3: helen.lopez605@example.com | D3: 230-295-4582 | E3: Brazil | F3: 44627
A4: 343962 | B4: Eric Cox | C4: eric.cox28@example.com | D4: 425-659-5557 | E4: Germany | F4: 45421
A5: 948749 | B5: James Lee | C5: james.lee715@example.com | D5: 484-359-4527 | E5: Brazil | F5: 45258
A6: 900581 | B6: Carol Wilson | C6: carol.wilson95@example.com | D6: 567-552-5333 | E6: India | F6: 44760
A7: 946335 | B7: Jennifer Collins | C7: jennifer.collins550@example.com | D7: 280-765-5803 | E7: Canada | F7: 45337
A8: 969693 | B8: Samuel Richardson | C8: samuel.richardson907@example.com | D8: 921-271-1750 | E8: Australia | F8: 44955
A9: 793384 | B9: Sandra Nguyen | C9: sandra.nguyen82@example.com | D9: 589-484-8428 | E9: France | F9: 44768
A10: 766563 | B10: Edward Lee | C10: edward.lee380@example.com | D10: 886-473-2169 | E10: Australia | F10: 44991
A11: 738720 | B11: Samantha Perez | C11: samantha.perez547@example.com | D11: 673-588-5422 | E11: France | F11: 44896
A12: 771088 | B12: Patrick Bailey | C12: patrick.bailey225@example.com | D12: 434-232-6168 | E12: Netherlands | F12: 44676
A13: 520651 | B13: Andrew Rodriguez | C13: andrew.rodriguez217@example.com | D13: 871-711-7482 | E13: Netherlands | F13: 44997
... A60: 442027 | B60: Stephanie Hughes | C60: stephanie.hughes303@example.com | D60: 630-880-7211 | E60: United Kingdom | F60: 44954
A61: 810219 | B61: Matthew Ward | C61: matthew.ward583@example.com | E61: Italy | F61: 45393
A62: 400850 | B62: Mark Parker | C62: mark.parker805@example.com | D62: 652-652-4501 | E62: Netherlands | F62: 45514
A63: 636004 | B63: Gary Perez | C63: gary.perez675@example.com | D63: 727-879-6491 | E63: United States | F63: 45143
A64: 197923 | B64: Steven Gray | C64: steven.gray318@example.com | D64: 350-225-1757 | E64: France | F64: 44969
A65: 356736 | B65: Gary Ward | C65: gary.ward871@example.com | D65: 624-844-4185 | E65: United States | F65: 45494
A66: 853240 | B66: Rachel Roberts | C66: rachel.roberts507@example.com | D66: 351-871-1090 | E66: India | F66: 45061
A67: 887443 | B67: Susan Diaz | C67: susan.diaz225@example.com | D67: 675-251-5082 | E67: United Kingdom | F67: 45622
A68: 989545 | B68: Jessica Collins | C68: jessica.collins137@example.com | D68: 772-809-6198 | E68: Mexico | F68: 45649
A69: 891937 | B69: Ryan Ward | C69: ryan.ward835@example.com | D69: 362-961-8777 | E69: Brazil | F69: 45475
A70: 571932 | B70: Kimberly Young | C70: kimberly.young861@example.com | D70: 696-841-4919 | E70: Spain | F70: 45629
A71: 387936 | B71: Ryan Martinez | C71: ryan.martinez731@example.com | D71: 478-543-6238 | E71: Italy | F71: 45042
A72: 666390 | B72: David Moore | C72: david.moore155@example.com | D72: 910-356-4505 | E72: France | F72: 45346
A73: 167348 | B73: Rebecca Evans | C73: rebecca.evans339@example.com | D73: 263-411-7883 | E73: Mexico | F73: 45413
... A82: 801978 | B82: Joseph Reed | C82: joseph.reed971@example.com | D82: 916-462-7043 | E82: Germany | F82: 45514
A83: 275939 | B83: Nicole Cox | C83: nicole.cox987@example.com | E83: Canada | F83: 44897
A84: 427110 | B84: Brenda Gray | C84: brenda.gray930@example.com | D84: 932-403-2245 | E84: India | F84: 45374
A85: 720859 | B85: Patrick Watson | C85: patrick.watson249@example.com | D85: 900-814-2983 | E85: Canada | F85: 45179
A86: 934904 | B86: Justin Garcia | C86: justin.garcia356@example.com | D86: 270-718-6590 | E86: Brazil | F86: 45320
A87: 113266 | B87: Rebecca Morales | C87: rebecca.morales109@example.com | D87: 850-670-3506 | E87: Brazil | F87: 45303
A88: 556641 | B88: Matthew Gutierrez | C88: matthew.gutierrez989@example.com | D88: 676-646-5397 | E88: Spain | F88: 45552
A89: 437960 | B89: Ashley Lopez | C89: ashley.lopez286@example.com | D89: 968-675-7209 | E89: Mexico | F89: 45061
A90: 452737 | B90: Patricia Murphy | C90: patricia.murphy872@example.com | D90: 699-417-6813 | E90: Netherlands | F90: 44934
A91: 936587 | B91: Kimberly Baker | C91: kimberly.baker287@example.com | D91: 729-395-2402 | E91: Spain | F91: 44582
A92: 353080 | B92: Jason Morales | C92: jason.morales569@example.com | D92: 861-928-9041 | E92: France | F92: 45537
A93: 569945 | B93: John Lopez | C93: john.lopez302@example.com | E93: France | F93: 45390
A94: 796212 | B94: Scott Mitchell | C94: scott.mitchell485@example.com | D94: 963-763-6419 | E94: Australia | F94: 45433
...

Sheet product_plans
A1: plan_id | B1: plan_name | C1: billing_cycle | D1: price
A2: 1000 | B2: Basic | C2: Monthly | D2: 19
A3: 1001 | B3: Basic | C3: Annual | D3: 190
A4: 1002 | B4: Standard | C4: Monthly | D4: 39
A5: 1003 | B5: Standard | C5: Annual | D5: 390
A6: 1004 | B6: Pro | C6: Monthly | D6: 79
A7: 1005 | B7: Pro | C7: Annual | D7: 790
A8: 1006 | B8: Team | C8: Monthly | D8: 149
A9: 1007 | B9: Team | C9: Annual | D9: 1490
A10: 1008 | B10: Enterprise | C10: Monthly | D10: 299
A11: 1009 | B11: Enterprise | C11: Annual | D11: 2990

Sheet subscriptions_clean
A1: subscription_id | B1: customer_id | C1: plan_id | D1: start_date | E1: end_date | F1: status | G1: customer_exists | H1: end_before_start | I1: status_end_mismatch | J1: is_valid_subscription
A2: 1968122 | B2: 955662 | C2: 1006 | D2: 45351 | E2: 45507 | F2: churned | G2: =IF(ISNA(_xlfn.XLOOKUP(subscriptions[[#This Row],[customer_id]], customers[customer_id], customers[customer_id])), "NO", "YES") -> YES | H2: =IF(AND(subscriptions[[#This Row],[end_date]]<>"", subscriptions[[#This Row],[end_date]] < subscriptions[[#This Row],[start_date]]), 1, 0) -> 0 | I2: =IF( OR( AND(subscriptions[[#This Row],[status]]="active", subscriptions[[#This Row],[end_date]]<>""), AND(subscriptions[[#This Row],[status]]="churned", subscriptions[[#This Row],[end_date]]="") ), 1, 0 ) -> 0 | J2: =IF( AND(subscriptions[[#This Row],[end_before_start]]=0, subscriptions[[#This Row],[status_end_mismatch]]=0), 1, 0 ) -> 1
A3: 5066006 | B3: 602681 | C3: 1000 | D3: 45540 | F3: active | G3: =IF(ISNA(_xlfn.XLOOKUP(subscriptions[[#This Row],[customer_id]], customers[customer_id], customers[customer_id])), "NO", "YES") -> YES | H3: =IF(AND(subscriptions[[#This Row],[end_date]]<>"", subscriptions[[#This Row],[end_date]] < subscriptions[[#This Row],[start_date]]), 1, 0) -> 0 | I3: =IF( OR( AND(subscriptions[[#This Row],[status]]="active", subscriptions[[#This Row],[end_date]]<>""), AND(subscriptions[[#This Row],[status]]="churned", subscriptions[[#This Row],[end_date]]="") ), 1, 0 ) -> 0 | J3: =IF( AND(subscriptions[[#This Row],[end_before_start]]=0, subscriptions[[#This Row],[status_end_mismatch]]=0), 1, 0 ) -> 1
A4: 7063525 | B4: 292811 | C4: 1005 | D4: 44619 | E4: 44979 | F4: churned | G4: =IF(ISNA(_xlfn.XLOOKUP(subscriptions[[#This Row],[customer_id]], customers[customer_id], customers[customer_id])), "NO", "YES") -> YES | H4: =IF(AND(subscriptions[[#This Row],[end_date]]<>"", subscriptions[[#This Row],[end_date]] < subscriptions[[#This Row],[start_date]]), 1, 0) -> 0 | I4: =IF( OR( AND(subscriptions[[#This Row],[status]]="active", subscriptions[[#This Row],[end_date]]<>""), AND(subscriptions[[#This Row],[status]]="churned", subscriptions[[#This Row],[end_date]]="") ), 1, 0 ) -> 0 | J4: =IF( AND(subscriptions[[#This Row],[end_before_start]]=0, subscriptions[[#This Row],[status_end_mismatch]]=0), 1, 0 ) -> 1
A5: 3481086 | B5: 789880 | C5: 1004 | D5: 45097 | E5: 45475 | F5: churned | G5: =IF(ISNA(_xlfn.XLOOKUP(subscriptions[[#This Row],[customer_id]], customers[customer_id], customers[customer_id])), "NO", "YES") -> YES | H5: =IF(AND(subscriptions[[#This Row],[end_date]]<>"", subscriptions[[#This Row],[end_date]] < subscriptions[[#This Row],[start_date]]), 1, 0) -> 0 | I5: =IF( OR( AND(subscriptions[[#This Row],[status]]="active", subscriptions[[#This Row],[end_date]]<>""), AND(subscriptions[[#This Row],[status]]="churned", subscriptions[[#This Row],[end_date]]="") ), 1, 0 ) -> 0 | J5: =IF( AND(subscriptions[[#This Row],[end_before_start]]=0, subscriptions[[#This Row],[status_end_mismatch]]=0), 1, 0 ) -> 1
A6: 3472414 | B6: 574012 | C6: 1008 | D6: 45082 | F6: active | G6: =IF(ISNA(_xlfn.XLOOKUP(subscriptions[[#This Row],[customer_id]], customers[customer_id], customers[customer_id])), "NO", "YES") -> YES | H6: =IF(AND(subscriptions[[#This Row],[end_date]]<>"", subscriptions[[#This Row],[end_date]] < subscriptions[[#This Row],[start_date]]), 1, 0) -> 0 | I6: =IF( OR( AND(subscriptions[[#This Row],[status]]="active", subscriptions[[#This Row],[end_date]]<>""), AND(subscriptions[[#This Row],[status]]="churned", subscriptions[[#This Row],[end_date]]="") ), 1, 0 ) -> 0 | J6: =IF( AND(subscriptions[[#This Row],[end_before_start]]=0, subscriptions[[#This Row],[status_end_mismatch]]=0), 1, 0 ) -> 1
A7: 3708302 | B7: 249375 | C7: 1004 | D7: 44587 | F7: active | G7: =IF(ISNA(_xlfn.XLOOKUP(subscriptions[[#This Row],[customer_id]], customers[customer_id], customers[customer_id])), "NO", "YES") -> YES | H7: =IF(AND(subscriptions[[#This Row],[end_date]]<>"", subscriptions[[#This Row],[end_date]] < subscriptions[[#This Row],[start_date]]), 1, 0) -> 0 | I7: =IF( OR( AND(subscriptions[[#This Row],[status]]="active", subscriptions[[#This Row],[end_date]]<>""), AND(subscriptions[[#This Row],[status]]="churned", subscriptions[[#This Row],[end_date]]="") ), 1, 0 ) -> 0 | J7: =IF( AND(subscriptions[[#This Row],[end_before_start]]=0, subscriptions[[#This Row],[status_end_mismatch]]=0), 1, 0 ) -> 1
A8: 2548634 | B8: 668373 | C8: 1004 | D8: 45349 | F8: active | G8: =IF(ISNA(_xlfn.XLOOKUP(subscriptions[[#This Row],[customer_id]], customers[customer_id], customers[customer_id])), "NO", "YES") -> YES | H8: =IF(AND(subscriptions[[#This Row],[end_date]]<>"", subscriptions[[#This Row],[end_date]] < subscriptions[[#This Row],[start_date]]), 1, 0) -> 0 | I8: =IF( OR( AND(subscriptions[[#This Row],[status]]="active", subscriptions[[#This Row],[end_date]]<>""), AND(subscriptions[[#This Row],[status]]="churned", subscriptions[[#This Row],[end_date]]="") ), 1, 0 ) -> 0 | J8: =IF( AND(subscriptions[[#This Row],[end_before_start]]=0, subscriptions[[#This Row],[status_end_mismatch]]=0), 1, 0 ) -> 1
A9: 2348021 | B9: 384218 | C9: 1002 | D9: 44948 | E9: 45062 | F9: churned | G9: =IF(ISNA(_xlfn.XLOOKUP(subscriptions[[#This Row],[customer_id]], customers[customer_id], customers[customer_id])), "NO", "YES") -> YES | H9: =IF(AND(subscriptions[[#This Row],[end_date]]<>"", subscriptions[[#This Row],[end_date]] < subscriptions[[#This Row],[start_date]]), 1, 0) -> 0 | I9: =IF( OR( AND(subscriptions[[#This Row],[status]]="active", subscriptions[[#This Row],[end_date]]<>""), AND(subscriptions[[#This Row],[status]]="churned", subscriptions[[#This Row],[end_date]]="") ), 1, 0 ) -> 0 | J9: =IF( AND(subscriptions[[#This Row],[end_before_start]]=0, subscriptions[[#This Row],[status_end_mismatch]]=0), 1, 0 ) -> 1
A10: 8161714 | B10: 537605 | C10: 1005 | D10: 45079 | E10: 45365 | F10: churned | G10: =IF(ISNA(_xlfn.XLOOKUP(subscriptions[[#This Row],[customer_id]], customers[customer_id], customers[customer_id])), "NO", "YES") -> YES | H10: =IF(AND(subscriptions[[#This Row],[end_date]]<>"", subscriptions[[#This Row],[end_date]] < subscriptions[[#This Row],[start_date]]), 1, 0) -> 0 | I10: =IF( OR( AND(subscriptions[[#This Row],[status]]="active", subscriptions[[#This Row],[end_date]]<>""), AND(subscriptions[[#This Row],[status]]="churned", subscriptions[[#This Row],[end_date]]="") ), 1, 0 ) -> 0 | J10: =IF( AND(subscriptions[[#This Row],[end_before_start]]=0, subscriptions[[#This Row],[status_end_mismatch]]=0), 1, 0 ) -> 1
A11: 9945633 | B11: 211579 | C11: 1000 | D11: 45345 | F11: active | G11: =IF(ISNA(_xlfn.XLOOKUP(subscriptions[[#This Row],[customer_id]], customers[customer_id], customers[customer_id])), "NO", "YES") -> YES | H11: =IF(AND(subscriptions[[#This Row],[end_date]]<>"", subscriptions[[#This Row],[end_date]] < subscriptions[[#This Row],[start_date]]), 1, 0) -> 0 | I11: =IF( OR( AND(subscriptions[[#This Row],[status]]="active", subscriptions[[#This Row],[end_date]]<>""), AND(subscriptions[[#This Row],[status]]="churned", subscriptions[[#This Row],[end_date]]="") ), 1, 0 ) -> 0 | J11: =IF( AND(subscriptions[[#This Row],[end_before_start]]=0, subscriptions[[#This Row],[status_end_mismatch]]=0), 1, 0 ) -> 1
A12: 7905652 | B12: 929090 | C12: 1006 | D12: 44744 | F12: active | G12: =IF(ISNA(_xlfn.XLOOKUP(subscriptions[[#This Row],[customer_id]], customers[customer_id], customers[customer_id])), "NO", "YES") -> YES | H12: =IF(AND(subscriptions[[#This Row],[end_date]]<>"", subscriptions[[#This Row],[end_date]] < subscriptions[[#This Row],[start_date]]), 1, 0) -> 0 | I12: =IF( OR( AND(subscriptions[[#This Row],[status]]="active", subscriptions[[#This Row],[end_date]]<>""), AND(subscriptions[[#This Row],[status]]="churned", subscriptions[[#This Row],[end_date]]="") ), 1, 0 ) -> 0 | J12: =IF( AND(subscriptions[[#This Row],[end_before_start]]=0, subscriptions[[#This Row],[status_end_mismatch]]=0), 1, 0 ) -> 1
A13: 6777952 | B13: 947684 | C13: 1001 | D13: 44854 | F13: active | G13: =IF(ISNA(_xlfn.XLOOKUP(subscriptions[[#This Row],[customer_id]], customers[customer_id], customers[customer_id])), "NO", "YES") -> YES | H13: =IF(AND(subscriptions[[#This Row],[end_date]]<>"", subscriptions[[#This Row],[end_date]] < subscriptions[[#This Row],[start_date]]), 1, 0) -> 0 | I13: =IF( OR( AND(subscriptions[[#This Row],[status]]="active", subscriptions[[#This Row],[end_date]]<>""), AND(subscriptions[[#This Row],[status]]="churned", subscriptions[[#This Row],[end_date]]="") ), 1, 0 ) -> 0 | J13: =IF( AND(subscriptions[[#This Row],[end_before_start]]=0, subscriptions[[#This Row],[status_end_mismatch]]=0), 1, 0 ) -> 1
A14: 4515255 | B14: 268546 | C14: 1000 | D14: 45377 | E14: 45410 | F14: churned | G14: =IF(ISNA(_xlfn.XLOOKUP(subscriptions[[#This Row],[customer_id]], customers[customer_id], customers[customer_id])), "NO", "YES") -> YES | H14: =IF(AND(subscriptions[[#This Row],[end_date]]<>"", subscriptions[[#This Row],[end_date]] < subscriptions[[#This Row],[start_date]]), 1, 0) -> 0 | I14: =IF( OR( AND(subscriptions[[#This Row],[status]]="active", subscriptions[[#This Row],[end_date]]<>""), AND(subscriptions[[#This Row],[status]]="churned", subscriptions[[#This Row],[end_date]]="") ), 1, 0 ) -> 0 | J14: =IF( AND(subscriptions[[#This Row],[end_before_start]]=0, subscriptions[[#This Row],[status_end_mismatch]]=0), 1, 0 ) -> 1
A15: 3825261 | B15: 536646 | C15: 1000 | D15: 45569 | F15: active | G15: =IF(ISNA(_xlfn.XLOOKUP(subscriptions[[#This Row],[customer_id]], customers[customer_id], customers[customer_id])), "NO", "YES") -> YES | H15: =IF(AND(subscriptions[[#This Row],[end_date]]<>"", subscriptions[[#This Row],[end_date]] < subscriptions[[#This Row],[start_date]]), 1, 0) -> 0 | I15: =IF( OR( AND(subscriptions[[#This Row],[status]]="active", subscriptions[[#This Row],[end_date]]<>""), AND(subscriptions[[#This Row],[status]]="churned", subscriptions[[#This Row],[end_date]]="") ), 1, 0 ) -> 0 | J15: =IF( AND(subscriptions[[#This Row],[end_before_start]]=0, subscriptions[[#This Row],[status_end_mismatch]]=0), 1, 0 ) -> 1
A16: 2171745 | B16: 972064 | C16: 1009 | D16: 45417 | F16: active | G16: =IF(ISNA(_xlfn.XLOOKUP(subscriptions[[#This Row],[customer_id]], customers[customer_id], customers[customer_id])), "NO", "YES") -> YES | H16: =IF(AND(subscriptions[[#This Row],[end_date]]<>"", subscriptions[[#This Row],[end_date]] < subscriptions[[#This Row],[start_date]]), 1, 0) -> 0 | I16: =IF( OR( AND(subscriptions[[#This Row],[status]]="active", subscriptions[[#This Row],[end_date]]<>""), AND(subscriptions[[#This Row],[status]]="churned", subscriptions[[#This Row],[end_date]]="") ), 1, 0 ) -> 0 | J16: =IF( AND(subscriptions[[#This Row],[end_before_start]]=0, subscriptions[[#This Row],[status_end_mismatch]]=0), 1, 0 ) -> 1
A17: 5837546 | B17: 854701 | C17: 1002 | D17: 45444 | F17: active | G17: =IF(ISNA(_xlfn.XLOOKUP(subscriptions[[#This Row],[customer_id]], customers[customer_id], customers[customer_id])), "NO", "YES") -> YES | H17: =IF(AND(subscriptions[[#This Row],[end_date]]<>"", subscriptions[[#This Row],[end_date]] < subscriptions[[#This Row],[start_date]]), 1, 0) -> 0 | I17: =IF( OR( AND(subscriptions[[#This Row],[status]]="active", subscriptions[[#This Row],[end_date]]<>""), AND(subscriptions[[#This Row],[status]]="churned", subscriptions[[#This Row],[end_date]]="") ), 1, 0 ) -> 0 | J17: =IF( AND(subscriptions[[#This Row],[end_before_start]]=0, subscriptions[[#This Row],[status_end_mismatch]]=0), 1, 0 ) -> 1
A18: 7285607 | B18: 448098 | C18: 1007 | D18: 44943 | E18: 45074 | F18: churned | G18: =IF(ISNA(_xlfn.XLOOKUP(subscriptions[[#This Row],[customer_id]], customers[customer_id], customers[customer_id])), "NO", "YES") -> YES | H18: =IF(AND(subscriptions[[#This Row],[end_date]]<>"", subscriptions[[#This Row],[end_date]] < subscriptions[[#This Row],[start_date]]), 1, 0) -> 0 | I18: =IF( OR( AND(subscriptions[[#This Row],[status]]="active", subscriptions[[#This Row],[end_date]]<>""), AND(subscriptions[[#This Row],[status]]="churned", subscriptions[[#This Row],[end_date]]="") ), 1, 0 ) -> 0 | J18: =IF( AND(subscriptions[[#This Row],[end_before_start]]=0, subscriptions[[#This Row],[status_end_mismatch]]=0), 1, 0 ) -> 1
A19: 9161633 | B19: 546157 | C19: 1006 | D19: 44934 | F19: active | G19: =IF(ISNA(_xlfn.XLOOKUP(subscriptions[[#This Row],[customer_id]], customers[customer_id], customers[customer_id])), "NO", "YES") -> YES | H19: =IF(AND(subscriptions[[#This Row],[end_date]]<>"", subscriptions[[#This Row],[end_date]] < subscriptions[[#This Row],[start_date]]), 1, 0) -> 0 | I19: =IF( OR( AND(subscriptions[[#This Row],[status]]="active", subscriptions[[#This Row],[end_date]]<>""), AND(subscriptions[[#This Row],[status]]="churned", subscriptions[[#This Row],[end_date]]="") ), 1, 0 ) -> 0 | J19: =IF( AND(subscriptions[[#This Row],[end_before_start]]=0, subscriptions[[#This Row],[status_end_mismatch]]=0), 1, 0 ) -> 1
A20: 2849490 | B20: 694223 | C20: 1004 | D20: 45484 | F20: active | G20: =IF(ISNA(_xlfn.XLOOKUP(subscriptions[[#This Row],[customer_id]], customers[customer_id], customers[customer_id])), "NO", "YES") -> YES | H20: =IF(AND(subscriptions[[#This Row],[end_date]]<>"", subscriptions[[#This Row],[end_date]] < subscriptions[[#This Row],[start_date]]), 1, 0) -> 0 | I20: =IF( OR( AND(subscriptions[[#This Row],[status]]="active", subscriptions[[#This Row],[end_date]]<>""), AND(subscriptions[[#This Row],[status]]="churned", subscriptions[[#This Row],[end_date]]="") ), 1, 0 ) -> 0 | J20: =IF( AND(subscriptions[[#This Row],[end_before_start]]=0, subscriptions[[#This Row],[status_end_mismatch]]=0), 1, 0 ) -> 1
A21: 4566389 | B21: 270387 | C21: 1007 | D21: 44942 | F21: active | G21: =IF(ISNA(_xlfn.XLOOKUP(subscriptions[[#This Row],[customer_id]], customers[customer_id], customers[customer_id])), "NO", "YES") -> YES | H21: =IF(AND(subscriptions[[#This Row],[end_date]]<>"", subscriptions[[#This Row],[end_date]] < subscriptions[[#This Row],[start_date]]), 1, 0) -> 0 | I21: =IF( OR( AND(subscriptions[[#This Row],[status]]="active", subscriptions[[#This Row],[end_date]]<>""), AND(subscriptions[[#This Row],[status]]="churned", subscriptions[[#This Row],[end_date]]="") ), 1, 0 ) -> 0 | J21: =IF( AND(subscriptions[[#This Row],[end_before_start]]=0, subscriptions[[#This Row],[status_end_mismatch]]=0), 1, 0 ) -> 1
A22: 4065690 | B22: 621433 | C22: 1003 | D22: 44954 | F22: active | G22: =IF(ISNA(_xlfn.XLOOKUP(subscriptions[[#This Row],[customer_id]], customers[customer_id], customers[customer_id])), "NO", "YES") -> YES | H22: =IF(AND(subscriptions[[#This Row],[end_date]]<>"", subscriptions[[#This Row],[end_date]] < subscriptions[[#This Row],[start_date]]), 1, 0) -> 0 | I22: =IF( OR( AND(subscriptions[[#This Row],[status]]="active", subscriptions[[#This Row],[end_date]]<>""), AND(subscriptions[[#This Row],[status]]="churned", subscriptions[[#This Row],[end_date]]="") ), 1, 0 ) -> 0 | J22: =IF( AND(subscriptions[[#This Row],[end_before_start]]=0, subscriptions[[#This Row],[status_end_mismatch]]=0), 1, 0 ) -> 1
A23: 7858398 | B23: 861253 | C23: 1006 | D23: 45464 | E23: 45654 | F23: churned | G23: =IF(ISNA(_xlfn.XLOOKUP(subscriptions[[#This Row],[customer_id]], customers[customer_id], customers[customer_id])), "NO", "YES") -> YES | H23: =IF(AND(subscriptions[[#This Row],[end_date]]<>"", subscriptions[[#This Row],[end_date]] < subscriptions[[#This Row],[start_date]]), 1, 0) -> 0 | I23: =IF( OR( AND(subscriptions[[#This Row],[status]]="active", subscriptions[[#This Row],[end_date]]<>""), AND(subscriptions[[#This Row],[status]]="churned", subscriptions[[#This Row],[end_date]]="") ), 1, 0 ) -> 0 | J23: =IF( AND(subscriptions[[#This Row],[end_before_start]]=0, subscriptions[[#This Row],[status_end_mismatch]]=0), 1, 0 ) -> 1
A24: 3787134 | B24: 601903 | C24: 1008 | D24: 44725 | F24: active | G24: =IF(ISNA(_xlfn.XLOOKUP(subscriptions[[#This Row],[customer_id]], customers[customer_id], customers[customer_id])), "NO", "YES") -> YES | H24: =IF(AND(subscriptions[[#This Row],[end_date]]<>"", subscriptions[[#This Row],[end_date]] < subscriptions[[#This Row],[start_date]]), 1, 0) -> 0 | I24: =IF( OR( AND(subscriptions[[#This Row],[status]]="active", subscriptions[[#This Row],[end_date]]<>""), AND(subscriptions[[#This Row],[status]]="churned", subscriptions[[#This Row],[end_date]]="") ), 1, 0 ) -> 0 | J24: =IF( AND(subscriptions[[#This Row],[end_before_start]]=0, subscriptions[[#This Row],[status_end_mismatch]]=0), 1, 0 ) -> 1
A25: 7337233 | B25: 771088 | C25: 1001 | D25: 44817 | F25: active | G25: =IF(ISNA(_xlfn.XLOOKUP(subscriptions[[#This Row],[customer_id]], customers[customer_id], customers[customer_id])), "NO", "YES") -> YES | H25: =IF(AND(subscriptions[[#This Row],[end_date]]<>"", subscriptions[[#This Row],[end_date]] < subscriptions[[#This Row],[start_date]]), 1, 0) -> 0 | I25: =IF( OR( AND(subscriptions[[#This Row],[status]]="active", subscriptions[[#This Row],[end_date]]<>""), AND(subscriptions[[#This Row],[status]]="churned", subscriptions[[#This Row],[end_date]]="") ), 1, 0 ) -> 0 | J25: =IF( AND(subscriptions[[#This Row],[end_before_start]]=0, subscriptions[[#This Row],[status_end_mismatch]]=0), 1, 0 ) -> 1
A26: 6740356 | B26: 597643 | C26: 1000 | D26: 44622 | F26: active | G26: =IF(ISNA(_xlfn.XLOOKUP(subscriptions[[#This Row],[customer_id]], customers[customer_id], customers[customer_id])), "NO", "YES") -> YES | H26: =IF(AND(subscriptions[[#This Row],[end_date]]<>"", subscriptions[[#This Row],[end_date]] < subscriptions[[#This Row],[start_date]]), 1, 0) -> 0 | I26: =IF( OR( AND(subscriptions[[#This Row],[status]]="active", subscriptions[[#This Row],[end_date]]<>""), AND(subscriptions[[#This Row],[status]]="churned", subscriptions[[#This Row],[end_date]]="") ), 1, 0 ) -> 0 | J26: =IF( AND(subscriptions[[#This Row],[end_before_start]]=0, subscriptions[[#This Row],[status_end_mismatch]]=0), 1, 0 ) -> 1
A27: 9017783 | B27: 950576 | C27: 1007 | D27: 45555 | E27: 45636 | F27: churned | G27: =IF(ISNA(_xlfn.XLOOKUP(subscriptions[[#This Row],[customer_id]], customers[customer_id], customers[customer_id])), "NO", "YES") -> YES | H27: =IF(AND(subscriptions[[#This Row],[end_date]]<>"", subscriptions[[#This Row],[end_date]] < subscriptions[[#This Row],[start_date]]), 1, 0) -> 0 | I27: =IF( OR( AND(subscriptions[[#This Row],[status]]="active", subscriptions[[#This Row],[end_date]]<>""), AND(subscriptions[[#This Row],[status]]="churned", subscriptions[[#This Row],[end_date]]="") ), 1, 0 ) -> 0 | J27: =IF( AND(subscriptions[[#This Row],[end_before_start]]=0, subscriptions[[#This Row],[status_end_mismatch]]=0), 1, 0 ) -> 1
A28: 1159493 | B28: 852470 | C28: 1006 | D28: 44687 | F28: active | G28: =IF(ISNA(_xlfn.XLOOKUP(subscriptions[[#This Row],[customer_id]], customers[customer_id], customers[customer_id])), "NO", "YES") -> YES | H28: =IF(AND(subscriptions[[#This Row],[end_date]]<>"", subscriptions[[#This Row],[end_date]] < subscriptions[[#This Row],[start_date]]), 1, 0) -> 0 | I28: =IF( OR( AND(subscriptions[[#This Row],[status]]="active", subscriptions[[#This Row],[end_date]]<>""), AND(subscriptions[[#This Row],[status]]="churned", subscriptions[[#This Row],[end_date]]="") ), 1, 0 ) -> 0 | J28: =IF( AND(subscriptions[[#This Row],[end_before_start]]=0, subscriptions[[#This Row],[status_end_mismatch]]=0), 1, 0 ) -> 1
A29: 1121243 | B29: 124906 | C29: 1004 | D29: 44647 | F29: active | G29: =IF(ISNA(_xlfn.XLOOKUP(subscriptions[[#This Row],[customer_id]], customers[customer_id], customers[customer_id])), "NO", "YES") -> YES | H29: =IF(AND(subscriptions[[#This Row],[end_date]]<>"", subscriptions[[#This Row],[end_date]] < subscriptions[[#This Row],[start_date]]), 1, 0) -> 0 | I29: =IF( OR( AND(subscriptions[[#This Row],[status]]="active", subscriptions[[#This Row],[end_date]]<>""), AND(subscriptions[[#This Row],[status]]="churned", subscriptions[[#This Row],[end_date]]="") ), 1, 0 ) -> 0 | J29: =IF( AND(subscriptions[[#This Row],[end_before_start]]=0, subscriptions[[#This Row],[status_end_mismatch]]=0), 1, 0 ) -> 1
A30: 9763319 | B30: 520651 | C30: 1005 | D30: 44576 | F30: active | G30: =IF(ISNA(_xlfn.XLOOKUP(subscriptions[[#This Row],[customer_id]], customers[customer_id], customers[customer_id])), "NO", "YES") -> YES | H30: =IF(AND(subscriptions[[#This Row],[end_date]]<>"", subscriptions[[#This Row],[end_date]] < subscriptions[[#This Row],[start_date]]), 1, 0) -> 0 | I30: =IF( OR( AND(subscriptions[[#This Row],[status]]="active", subscriptions[[#This Row],[end_date]]<>""), AND(subscriptions[[#This Row],[status]]="churned", subscriptions[[#This Row],[end_date]]="") ), 1, 0 ) -> 0 | J30: =IF( AND(subscriptions[[#This Row],[end_before_start]]=0, subscriptions[[#This Row],[status_end_mismatch]]=0), 1, 0 ) -> 1
A31: 9725395 | B31: 983456 | C31: 1007 | D31: 45106 | E31: 45378 | F31: churned | G31: =IF(ISNA(_xlfn.XLOOKUP(subscriptions[[#This Row],[customer_id]], customers[customer_id], customers[customer_id])), "NO", "YES") -> YES | H31: =IF(AND(subscriptions[[#This Row],[end_date]]<>"", subscriptions[[#This Row],[end_date]] < subscriptions[[#This Row],[start_date]]), 1, 0) -> 0 | I31: =IF( OR( AND(subscriptions[[#This Row],[status]]="active", subscriptions[[#This Row],[end_date]]<>""), AND(subscriptions[[#This Row],[status]]="churned", subscriptions[[#This Row],[end_date]]="") ), 1, 0 ) -> 0 | J31: =IF( AND(subscriptions[[#This Row],[end_before_start]]=0, subscriptions[[#This Row],[status_end_mismatch]]=0), 1, 0 ) -> 1
A32: 6654424 | B32: 100716 | C32: 1002 | D32: 45441 | F32: active | G32: =IF(ISNA(_xlfn.XLOOKUP(subscriptions[[#This Row],[customer_id]], customers[customer_id], customers[customer_id])), "NO", "YES") -> YES | H32: =IF(AND(subscriptions[[#This Row],[end_date]]<>"", subscriptions[[#This Row],[end_date]] < subscriptions[[#This Row],[start_date]]), 1, 0) -> 0 | I32: =IF( OR( AND(subscriptions[[#This Row],[status]]="active", subscriptions[[#This Row],[end_date]]<>""), AND(subscriptions[[#This Row],[status]]="churned", subscriptions[[#This Row],[end_date]]="") ), 1, 0 ) -> 0 | J32: =IF( AND(subscriptions[[#This Row],[end_before_start]]=0, subscriptions[[#This Row],[status_end_mismatch]]=0), 1, 0 ) -> 1
A33: 6755884 | B33: 376021 | C33: 1007 | D33: 45207 | E33: 45421 | F33: churned | G33: =IF(ISNA(_xlfn.XLOOKUP(subscriptions[[#This Row],[customer_id]], customers[customer_id], customers[customer_id])), "NO", "YES") -> YES | H33: =IF(AND(subscriptions[[#This Row],[end_date]]<>"", subscriptions[[#This Row],[end_date]] < subscriptions[[#This Row],[start_date]]), 1, 0) -> 0 | I33: =IF( OR( AND(subscriptions[[#This Row],[status]]="active", subscriptions[[#This Row],[end_date]]<>""), AND(subscriptions[[#This Row],[status]]="churned", subscriptions[[#This Row],[end_date]]="") ), 1, 0 ) -> 0 | J33: =IF( AND(subscriptions[[#This Row],[end_before_start]]=0, subscriptions[[#This Row],[status_end_mismatch]]=0), 1, 0 ) -> 1
A34: 7685239 | B34: 236543 | C34: 1006 | D34: 45337 | E34: 45549 | F34: churned | G34: =IF(ISNA(_xlfn.XLOOKUP(subscriptions[[#This Row],[customer_id]], customers[customer_id], customers[customer_id])), "NO", "YES") -> YES | H34: =IF(AND(subscriptions[[#This Row],[end_date]]<>"", subscriptions[[#This Row],[end_date]] < subscriptions[[#This Row],[start_date]]), 1, 0) -> 0 | I34: =IF( OR( AND(subscriptions[[#This Row],[status]]="active", subscriptions[[#This Row],[end_date]]<>""), AND(subscriptions[[#This Row],[status]]="churned", subscriptions[[#This Row],[end_date]]="") ), 1, 0 ) -> 0 | J34: =IF( AND(subscriptions[[#This Row],[end_before_start]]=0, subscriptions[[#This Row],[status_end_mismatch]]=0), 1, 0 ) -> 1
A35: 6540763 | B35: 544278 | C35: 1008 | D35: 44767 | F35: active | G35: =IF(ISNA(_xlfn.XLOOKUP(subscriptions[[#This Row],[customer_id]], customers[customer_id], customers[customer_id])), "NO", "YES") -> YES | H35: =IF(AND(subscriptions[[#This Row],[end_date]]<>"", subscriptions[[#This Row],[end_date]] < subscriptions[[#This Row],[start_date]]), 1, 0) -> 0 | I35: =IF( OR( AND(subscriptions[[#This Row],[status]]="active", subscriptions[[#This Row],[end_date]]<>""), AND(subscriptions[[#This Row],[status]]="churned", subscriptions[[#This Row],[end_date]]="") ), 1, 0 ) -> 0 | J35: =IF( AND(subscriptions[[#This Row],[end_before_start]]=0, subscriptions[[#This Row],[status_end_mismatch]]=0), 1, 0 ) -> 1
A36: 7741225 | B36: 753425 | C36: 1003 | D36: 44846 | F36: active | G36: =IF(ISNA(_xlfn.XLOOKUP(subscriptions[[#This Row],[customer_id]], customers[customer_id], customers[customer_id])), "NO", "YES") -> YES | H36: =IF(AND(subscriptions[[#This Row],[end_date]]<>"", subscriptions[[#This Row],[end_date]] < subscriptions[[#This Row],[start_date]]), 1, 0) -> 0 | I36: =IF( OR( AND(subscriptions[[#This Row],[status]]="active", subscriptions[[#This Row],[end_date]]<>""), AND(subscriptions[[#This Row],[status]]="churned", subscriptions[[#This Row],[end_date]]="") ), 1, 0 ) -> 0 | J36: =IF( AND(subscriptions[[#This Row],[end_before_start]]=0, subscriptions[[#This Row],[status_end_mismatch]]=0), 1, 0 ) -> 1
A37: 3061828 | B37: 532322 | C37: 1008 | D37: 45134 | E37: 45291 | F37: churned | G37: =IF(ISNA(_xlfn.XLOOKUP(subscriptions[[#This Row],[customer_id]], customers[customer_id], customers[customer_id])), "NO", "YES") -> YES | H37: =IF(AND(subscriptions[[#This Row],[end_date]]<>"", subscriptions[[#This Row],[end_date]] < subscriptions[[#This Row],[start_date]]), 1, 0) -> 0 | I37: =IF( OR( AND(subscriptions[[#This Row],[status]]="active", subscriptions[[#This Row],[end_date]]<>""), AND(subscriptions[[#This Row],[status]]="churned", subscriptions[[#This Row],[end_date]]="") ), 1, 0 ) -> 0 | J37: =IF( AND(subscriptions[[#This Row],[end_before_start]]=0, subscriptions[[#This Row],[status_end_mismatch]]=0), 1, 0 ) -> 1
A38: 7181227 | B38: 506951 | C38: 1007 | D38: 45487 | E38: 45630 | F38: churned | G38: =IF(ISNA(_xlfn.XLOOKUP(subscriptions[[#This Row],[customer_id]], customers[customer_id], customers[customer_id])), "NO", "YES") -> YES | H38: =IF(AND(subscriptions[[#This Row],[end_date]]<>"", subscriptions[[#This Row],[end_date]] < subscriptions[[#This Row],[start_date]]), 1, 0) -> 0 | I38: =IF( OR( AND(subscriptions[[#This Row],[status]]="active", subscriptions[[#This Row],[end_date]]<>""), AND(subscriptions[[#This Row],[status]]="churned", subscriptions[[#This Row],[end_date]]="") ), 1, 0 ) -> 0 | J38: =IF( AND(subscriptions[[#This Row],[end_before_start]]=0, subscriptions[[#This Row],[status_end_mismatch]]=0), 1, 0 ) -> 1
A39: 8972523 | B39: 156700 | C39: 1003 | D39: 45408 | E39: 45439 | F39: churned | G39: =IF(ISNA(_xlfn.XLOOKUP(subscriptions[[#This Row],[customer_id]], customers[customer_id], customers[customer_id])), "NO", "YES") -> YES | H39: =IF(AND(subscriptions[[#This Row],[end_date]]<>"", subscriptions[[#This Row],[end_date]] < subscriptions[[#This Row],[start_date]]), 1, 0) -> 0 | I39: =IF( OR( AND(subscriptions[[#This Row],[status]]="active", subscriptions[[#This Row],[end_date]]<>""), AND(subscriptions[[#This Row],[status]]="churned", subscriptions[[#This Row],[end_date]]="") ), 1, 0 ) -> 0 | J39: =IF( AND(subscriptions[[#This Row],[end_before_start]]=0, subscriptions[[#This Row],[status_end_mismatch]]=0), 1, 0 ) -> 1
A40: 6405343 | B40: 726909 | C40: 1004 | D40: 44596 | E40: 44649 | F40: churned | G40: =IF(ISNA(_xlfn.XLOOKUP(subscriptions[[#This Row],[customer_id]], customers[customer_id], customers[customer_id])), "NO", "YES") -> YES | H40: =IF(AND(subscriptions[[#This Row],[end_date]]<>"", subscriptions[[#This Row],[end_date]] < subscriptions[[#This Row],[start_date]]), 1, 0) -> 0 | I40: =IF( OR( AND(subscriptions[[#This Row],[status]]="active", subscriptions[[#This Row],[end_date]]<>""), AND(subscriptions[[#This Row],[status]]="churned", subscriptions[[#This Row],[end_date]]="") ), 1, 0 ) -> 0 | J40: =IF( AND(subscriptions[[#This Row],[end_before_start]]=0, subscriptions[[#This Row],[status_end_mismatch]]=0), 1, 0 ) -> 1
...

Sheet payments_clean
A1: payment_id | B1: subscription_id | C1: payment_date | D1: amount | E1: subscription_exists | F1: sub_start_date | G1: sub_end_date | H1: before_start | I1: after_end | J1: invalid_amount | K1: is_valid_payment
A2: 29070042 | B2: 8266453 | C2: 45364 | D2: 1490 | E2: =IF( ISNA( _xlfn.XLOOKUP( payments_raw[[#This Row],[subscription_id]], subscriptions[subscription_id], subscriptions[subscription_id] ) ), 0, 1 ) -> 1 | F2: =_xlfn.XLOOKUP(payments_raw[[#This Row],[subscription_id]], subscriptions[subscription_id], subscriptions[start_date]) -> 44970 | G2: =IF(_xlfn.XLOOKUP(payments_raw[[#This Row],[subscription_id]], subscriptions[subscription_id], subscriptions[end_date])=0,"",_xlfn.XLOOKUP(payments_raw[[#This Row],[subscription_id]], subscriptions[subscription_id], subscriptions[end_date])) | H2: =IF(payments_raw[[#This Row],[payment_date]] < payments_raw[[#This Row],[sub_start_date]], 1, 0) -> 0 | I2: =IF(AND(payments_raw[[#This Row],[sub_end_date]]<>"", payments_raw[[#This Row],[payment_date]] > payments_raw[[#This Row],[sub_end_date]]), 1, 0) -> 0 | J2: =IF(payments_raw[[#This Row],[amount]] <= 0, 1, 0) -> 0 | K2: =IF( AND( payments_raw[[#This Row],[subscription_exists]]=1, payments_raw[[#This Row],[before_start]]=0, payments_raw[[#This Row],[after_end]]=0, payments_raw[[#This Row],[invalid_amount]]=0 ), 1, 0 ) -> 1
A3: 13285625 | B3: 3457722 | C3: 44997 | D3: 149 | E3: =IF( ISNA( _xlfn.XLOOKUP( payments_raw[[#This Row],[subscription_id]], subscriptions[subscription_id], subscriptions[subscription_id] ) ), 0, 1 ) -> 1 | F3: =_xlfn.XLOOKUP(payments_raw[[#This Row],[subscription_id]], subscriptions[subscription_id], subscriptions[start_date]) -> 44855 | G3: =IF(_xlfn.XLOOKUP(payments_raw[[#This Row],[subscription_id]], subscriptions[subscription_id], subscriptions[end_date])=0,"",_xlfn.XLOOKUP(payments_raw[[#This Row],[subscription_id]], subscriptions[subscription_id], subscriptions[end_date])) | H3: =IF(payments_raw[[#This Row],[payment_date]] < payments_raw[[#This Row],[sub_start_date]], 1, 0) -> 0 | I3: =IF(AND(payments_raw[[#This Row],[sub_end_date]]<>"", payments_raw[[#This Row],[payment_date]] > payments_raw[[#This Row],[sub_end_date]]), 1, 0) -> 0 | J3: =IF(payments_raw[[#This Row],[amount]] <= 0, 1, 0) -> 0 | K3: =IF( AND( payments_raw[[#This Row],[subscription_exists]]=1, payments_raw[[#This Row],[before_start]]=0, payments_raw[[#This Row],[after_end]]=0, payments_raw[[#This Row],[invalid_amount]]=0 ), 1, 0 ) -> 1
A4: 61198338 | B4: 3376783 | C4: 45213 | D4: 149 | E4: =IF( ISNA( _xlfn.XLOOKUP( payments_raw[[#This Row],[subscription_id]], subscriptions[subscription_id], subscriptions[subscription_id] ) ), 0, 1 ) -> 1 | F4: =_xlfn.XLOOKUP(payments_raw[[#This Row],[subscription_id]], subscriptions[subscription_id], subscriptions[start_date]) -> 45175 | G4: =IF(_xlfn.XLOOKUP(payments_raw[[#This Row],[subscription_id]], subscriptions[subscription_id], subscriptions[end_date])=0,"",_xlfn.XLOOKUP(payments_raw[[#This Row],[subscription_id]], subscriptions[subscription_id], subscriptions[end_date])) -> 45315 | H4: =IF(payments_raw[[#This Row],[payment_date]] < payments_raw[[#This Row],[sub_start_date]], 1, 0) -> 0 | I4: =IF(AND(payments_raw[[#This Row],[sub_end_date]]<>"", payments_raw[[#This Row],[payment_date]] > payments_raw[[#This Row],[sub_end_date]]), 1, 0) -> 0 | J4: =IF(payments_raw[[#This Row],[amount]] <= 0, 1, 0) -> 0 | K4: =IF( AND( payments_raw[[#This Row],[subscription_exists]]=1, payments_raw[[#This Row],[before_start]]=0, payments_raw[[#This Row],[after_end]]=0, payments_raw[[#This Row],[invalid_amount]]=0 ), 1, 0 ) -> 1
A5: 11872359 | B5: 6196562 | C5: 45203 | D5: 19 | E5: =IF( ISNA( _xlfn.XLOOKUP( payments_raw[[#This Row],[subscription_id]], subscriptions[subscription_id], subscriptions[subscription_id] ) ), 0, 1 ) -> 1 | F5: =_xlfn.XLOOKUP(payments_raw[[#This Row],[subscription_id]], subscriptions[subscription_id], subscriptions[start_date]) -> 44981 | G5: =IF(_xlfn.XLOOKUP(payments_raw[[#This Row],[subscription_id]], subscriptions[subscription_id], subscriptions[end_date])=0,"",_xlfn.XLOOKUP(payments_raw[[#This Row],[subscription_id]], subscriptions[subscription_id], subscriptions[end_date])) -> 45345 | H5: =IF(payments_raw[[#This Row],[payment_date]] < payments_raw[[#This Row],[sub_start_date]], 1, 0) -> 0 | I5: =IF(AND(payments_raw[[#This Row],[sub_end_date]]<>"", payments_raw[[#This Row],[payment_date]] > payments_raw[[#This Row],[sub_end_date]]), 1, 0) -> 0 | J5: =IF(payments_raw[[#This Row],[amount]] <= 0, 1, 0) -> 0 | K5: =IF( AND( payments_raw[[#This Row],[subscription_exists]]=1, payments_raw[[#This Row],[before_start]]=0, payments_raw[[#This Row],[after_end]]=0, payments_raw[[#This Row],[invalid_amount]]=0 ), 1, 0 ) -> 1
A6: 98821543 | B6: 2945459 | C6: 45528 | D6: 1490 | E6: =IF( ISNA( _xlfn.XLOOKUP( payments_raw[[#This Row],[subscription_id]], subscriptions[subscription_id], subscriptions[subscription_id] ) ), 0, 1 ) -> 1 | F6: =_xlfn.XLOOKUP(payments_raw[[#This Row],[subscription_id]], subscriptions[subscription_id], subscriptions[start_date]) -> 45484 | G6: =IF(_xlfn.XLOOKUP(payments_raw[[#This Row],[subscription_id]], subscriptions[subscription_id], subscriptions[end_date])=0,"",_xlfn.XLOOKUP(payments_raw[[#This Row],[subscription_id]], subscriptions[subscription_id], subscriptions[end_date])) | H6: =IF(payments_raw[[#This Row],[payment_date]] < payments_raw[[#This Row],[sub_start_date]], 1, 0) -> 0 | I6: =IF(AND(payments_raw[[#This Row],[sub_end_date]]<>"", payments_raw[[#This Row],[payment_date]] > payments_raw[[#This Row],[sub_end_date]]), 1, 0) -> 0 | J6: =IF(payments_raw[[#This Row],[amount]] <= 0, 1, 0) -> 0 | K6: =IF( AND( payments_raw[[#This Row],[subscription_exists]]=1, payments_raw[[#This Row],[before_start]]=0, payments_raw[[#This Row],[after_end]]=0, payments_raw[[#This Row],[invalid_amount]]=0 ), 1, 0 ) -> 1
A7: 34683931 | B7: 2084084 | C7: 45276 | D7: 2242.5 | E7: =IF( ISNA( _xlfn.XLOOKUP( payments_raw[[#This Row],[subscription_id]], subscriptions[subscription_id], subscriptions[subscription_id] ) ), 0, 1 ) -> 1 | F7: =_xlfn.XLOOKUP(payments_raw[[#This Row],[subscription_id]], subscriptions[subscription_id], subscriptions[start_date]) -> 45165 | G7: =IF(_xlfn.XLOOKUP(payments_raw[[#This Row],[subscription_id]], subscriptions[subscription_id], subscriptions[end_date])=0,"",_xlfn.XLOOKUP(payments_raw[[#This Row],[subscription_id]], subscriptions[subscription_id], subscriptions[end_date])) | H7: =IF(payments_raw[[#This Row],[payment_date]] < payments_raw[[#This Row],[sub_start_date]], 1, 0) -> 0 | I7: =IF(AND(payments_raw[[#This Row],[sub_end_date]]<>"", payments_raw[[#This Row],[payment_date]] > payments_raw[[#This Row],[sub_end_date]]), 1, 0) -> 0 | J7: =IF(payments_raw[[#This Row],[amount]] <= 0, 1, 0) -> 0 | K7: =IF( AND( payments_raw[[#This Row],[subscription_exists]]=1, payments_raw[[#This Row],[before_start]]=0, payments_raw[[#This Row],[after_end]]=0, payments_raw[[#This Row],[invalid_amount]]=0 ), 1, 0 ) -> 1
A8: 73389452 | B8: 7288704 | C8: 44723 | D8: 79 | E8: =IF( ISNA( _xlfn.XLOOKUP( payments_raw[[#This Row],[subscription_id]], subscriptions[subscription_id], subscriptions[subscription_id] ) ), 0, 1 ) -> 1 | F8: =_xlfn.XLOOKUP(payments_raw[[#This Row],[subscription_id]], subscriptions[subscription_id], subscriptions[start_date]) -> 44704 | G8: =IF(_xlfn.XLOOKUP(payments_raw[[#This Row],[subscription_id]], subscriptions[subscription_id], subscriptions[end_date])=0,"",_xlfn.XLOOKUP(payments_raw[[#This Row],[subscription_id]], subscriptions[subscription_id], subscriptions[end_date])) -> 44830 | H8: =IF(payments_raw[[#This Row],[payment_date]] < payments_raw[[#This Row],[sub_start_date]], 1, 0) -> 0 | I8: =IF(AND(payments_raw[[#This Row],[sub_end_date]]<>"", payments_raw[[#This Row],[payment_date]] > payments_raw[[#This Row],[sub_end_date]]), 1, 0) -> 0 | J8: =IF(payments_raw[[#This Row],[amount]] <= 0, 1, 0) -> 0 | K8: =IF( AND( payments_raw[[#This Row],[subscription_exists]]=1, payments_raw[[#This Row],[before_start]]=0, payments_raw[[#This Row],[after_end]]=0, payments_raw[[#This Row],[invalid_amount]]=0 ), 1, 0 ) -> 1
A9: 36542426 | B9: 2728894 | C9: 44754 | D9: 19 | E9: =IF( ISNA( _xlfn.XLOOKUP( payments_raw[[#This Row],[subscription_id]], subscriptions[subscription_id], subscriptions[subscription_id] ) ), 0, 1 ) -> 1 | F9: =_xlfn.XLOOKUP(payments_raw[[#This Row],[subscription_id]], subscriptions[subscription_id], subscriptions[start_date]) -> 44743 | G9: =IF(_xlfn.XLOOKUP(payments_raw[[#This Row],[subscription_id]], subscriptions[subscription_id], subscriptions[end_date])=0,"",_xlfn.XLOOKUP(payments_raw[[#This Row],[subscription_id]], subscriptions[subscription_id], subscriptions[end_date])) -> 45081 | H9: =IF(payments_raw[[#This Row],[payment_date]] < payments_raw[[#This Row],[sub_start_date]], 1, 0) -> 0 | I9: =IF(AND(payments_raw[[#This Row],[sub_end_date]]<>"", payments_raw[[#This Row],[payment_date]] > payments_raw[[#This Row],[sub_end_date]]), 1, 0) -> 0 | J9: =IF(payments_raw[[#This Row],[amount]] <= 0, 1, 0) -> 0 | K9: =IF( AND( payments_raw[[#This Row],[subscription_exists]]=1, payments_raw[[#This Row],[before_start]]=0, payments_raw[[#This Row],[after_end]]=0, payments_raw[[#This Row],[invalid_amount]]=0 ), 1, 0 ) -> 1
A10: 31248859 | B10: 1675388 | C10: 45145 | D10: 190 | E10: =IF( ISNA( _xlfn.XLOOKUP( payments_raw[[#This Row],[subscription_id]], subscriptions[subscription_id], subscriptions[subscription_id] ) ), 0, 1 ) -> 1 | F10: =_xlfn.XLOOKUP(payments_raw[[#This Row],[subscription_id]], subscriptions[subscription_id], subscriptions[start_date]) -> 44835 | G10: =IF(_xlfn.XLOOKUP(payments_raw[[#This Row],[subscription_id]], subscriptions[subscription_id], subscriptions[end_date])=0,"",_xlfn.XLOOKUP(payments_raw[[#This Row],[subscription_id]], subscriptions[subscription_id], subscriptions[end_date])) | H10: =IF(payments_raw[[#This Row],[payment_date]] < payments_raw[[#This Row],[sub_start_date]], 1, 0) -> 0 | I10: =IF(AND(payments_raw[[#This Row],[sub_end_date]]<>"", payments_raw[[#This Row],[payment_date]] > payments_raw[[#This Row],[sub_end_date]]), 1, 0) -> 0 | J10: =IF(payments_raw[[#This Row],[amount]] <= 0, 1, 0) -> 0 | K10: =IF( AND( payments_raw[[#This Row],[subscription_exists]]=1, payments_raw[[#This Row],[before_start]]=0, payments_raw[[#This Row],[after_end]]=0, payments_raw[[#This Row],[invalid_amount]]=0 ), 1, 0 ) -> 1
A11: 83729641 | B11: 3860246 | C11: 45397 | D11: 2990 | E11: =IF( ISNA( _xlfn.XLOOKUP( payments_raw[[#This Row],[subscription_id]], subscriptions[subscription_id], subscriptions[subscription_id] ) ), 0, 1 ) -> 1 | F11: =_xlfn.XLOOKUP(payments_raw[[#This Row],[subscription_id]], subscriptions[subscription_id], subscriptions[start_date]) -> 45326 | G11: =IF(_xlfn.XLOOKUP(payments_raw[[#This Row],[subscription_id]], subscriptions[subscription_id], subscriptions[end_date])=0,"",_xlfn.XLOOKUP(payments_raw[[#This Row],[subscription_id]], subscriptions[subscription_id], subscriptions[end_date])) -> 45529 | H11: =IF(payments_raw[[#This Row],[payment_date]] < payments_raw[[#This Row],[sub_start_date]], 1, 0) -> 0 | I11: =IF(AND(payments_raw[[#This Row],[sub_end_date]]<>"", payments_raw[[#This Row],[payment_date]] > payments_raw[[#This Row],[sub_end_date]]), 1, 0) -> 0 | J11: =IF(payments_raw[[#This Row],[amount]] <= 0, 1, 0) -> 0 | K11: =IF( AND( payments_raw[[#This Row],[subscription_exists]]=1, payments_raw[[#This Row],[before_start]]=0, payments_raw[[#This Row],[after_end]]=0, payments_raw[[#This Row],[invalid_amount]]=0 ), 1, 0 ) -> 1
A12: 75301591 | B12: 3578194 | C12: 45272 | D12: 2990 | E12: =IF( ISNA( _xlfn.XLOOKUP( payments_raw[[#This Row],[subscription_id]], subscriptions[subscription_id], subscriptions[subscription_id] ) ), 0, 1 ) -> 1 | F12: =_xlfn.XLOOKUP(payments_raw[[#This Row],[subscription_id]], subscriptions[subscription_id], subscriptions[start_date]) -> 44651 | G12: =IF(_xlfn.XLOOKUP(payments_raw[[#This Row],[subscription_id]], subscriptions[subscription_id], subscriptions[end_date])=0,"",_xlfn.XLOOKUP(payments_raw[[#This Row],[subscription_id]], subscriptions[subscription_id], subscriptions[end_date])) | H12: =IF(payments_raw[[#This Row],[payment_date]] < payments_raw[[#This Row],[sub_start_date]], 1, 0) -> 0 | I12: =IF(AND(payments_raw[[#This Row],[sub_end_date]]<>"", payments_raw[[#This Row],[payment_date]] > payments_raw[[#This Row],[sub_end_date]]), 1, 0) -> 0 | J12: =IF(payments_raw[[#This Row],[amount]] <= 0, 1, 0) -> 0 | K12: =IF( AND( payments_raw[[#This Row],[subscription_exists]]=1, payments_raw[[#This Row],[before_start]]=0, payments_raw[[#This Row],[after_end]]=0, payments_raw[[#This Row],[invalid_amount]]=0 ), 1, 0 ) -> 1
A13: 68096981 | B13: 1854070 | C13: 45538 | D13: 39 | E13: =IF( ISNA( _xlfn.XLOOKUP( payments_raw[[#This Row],[subscription_id]], subscriptions[subscription_id], subscriptions[subscription_id] ) ), 0, 1 ) -> 1 | F13: =_xlfn.XLOOKUP(payments_raw[[#This Row],[subscription_id]], subscriptions[subscription_id], subscriptions[start_date]) -> 45427 | G13: =IF(_xlfn.XLOOKUP(payments_raw[[#This Row],[subscription_id]], subscriptions[subscription_id], subscriptions[end_date])=0,"",_xlfn.XLOOKUP(payments_raw[[#This Row],[subscription_id]], subscriptions[subscription_id], subscriptions[end_date])) | H13: =IF(payments_raw[[#This Row],[payment_date]] < payments_raw[[#This Row],[sub_start_date]], 1, 0) -> 0 | I13: =IF(AND(payments_raw[[#This Row],[sub_end_date]]<>"", payments_raw[[#This Row],[payment_date]] > payments_raw[[#This Row],[sub_end_date]]), 1, 0) -> 0 | J13: =IF(payments_raw[[#This Row],[amount]] <= 0, 1, 0) -> 0 | K13: =IF( AND( payments_raw[[#This Row],[subscription_exists]]=1, payments_raw[[#This Row],[before_start]]=0, payments_raw[[#This Row],[after_end]]=0, payments_raw[[#This Row],[invalid_amount]]=0 ), 1, 0 ) -> 1
... A3501: 57825619 | B3501: 1054096 | C3501: 45362 | D3501: 299 | E3501: =IF( ISNA( _xlfn.XLOOKUP( payments_raw[[#This Row],[subscription_id]], subscriptions[subscription_id], subscriptions[subscription_id] ) ), 0, 1 ) -> 1 | F3501: =_xlfn.XLOOKUP(payments_raw[[#This Row],[subscription_id]], subscriptions[subscription_id], subscriptions[start_date]) -> 45199 | G3501: =IF(_xlfn.XLOOKUP(payments_raw[[#This Row],[subscription_id]], subscriptions[subscription_id], subscriptions[end_date])=0,"",_xlfn.XLOOKUP(payments_raw[[#This Row],[subscription_id]], subscriptions[subscription_id], subscriptions[end_date])) | H3501: =IF(payments_raw[[#This Row],[payment_date]] < payments_raw[[#This Row],[sub_start_date]], 1, 0) -> 0 | I3501: =IF(AND(payments_raw[[#This Row],[sub_end_date]]<>"", payments_raw[[#This Row],[payment_date]] > payments_raw[[#This Row],[sub_end_date]]), 1, 0) -> 0 | J3501: =IF(payments_raw[[#This Row],[amount]] <= 0, 1, 0) -> 0 | K3501: =IF( AND( payments_raw[[#This Row],[subscription_exists]]=1, payments_raw[[#This Row],[before_start]]=0, payments_raw[[#This Row],[after_end]]=0, payments_raw[[#This Row],[invalid_amount]]=0 ), 1, 0 ) -> 1

Sheet marketing_events_clean
A1: event_id | B1: customer_id | C1: event_date | D1: channel | E1: customer_exists
A2: 834851529 | B2: 870214 | C2: 45419 | D2: Organic Search | E2: =IF(ISNUMBER(MATCH(marketing_events_raw[[#This Row],[customer_id]], customers_clean!A:A, 0)), 1, 0) -> 1
A3: 398267281 | B3: 894586 | C3: 45058 | D3: Organic Search | E3: =IF(ISNUMBER(MATCH(marketing_events_raw[[#This Row],[customer_id]], customers_clean!A:A, 0)), 1, 0) -> 1
A4: 814585584 | B4: 653429 | C4: 45452 | D4: Organic Search | E4: =IF(ISNUMBER(MATCH(marketing_events_raw[[#This Row],[customer_id]], customers_clean!A:A, 0)), 1, 0) -> 1
A5: 446253503 | B5: 555791 | C5: 45053 | D5: Partner | E5: =IF(ISNUMBER(MATCH(marketing_events_raw[[#This Row],[customer_id]], customers_clean!A:A, 0)), 1, 0) -> 1
A6: 914593189 | B6: 910326 | C6: 45116 | D6: Organic Search | E6: =IF(ISNUMBER(MATCH(marketing_events_raw[[#This Row],[customer_id]], customers_clean!A:A, 0)), 1, 0) -> 1
A7: 478026991 | B7: 297509 | C7: 44586 | D7: Facebook Ads | E7: =IF(ISNUMBER(MATCH(marketing_events_raw[[#This Row],[customer_id]], customers_clean!A:A, 0)), 1, 0) -> 1
A8: 373552584 | B8: 288056 | C8: 45345 | D8: Organic Search | E8: =IF(ISNUMBER(MATCH(marketing_events_raw[[#This Row],[customer_id]], customers_clean!A:A, 0)), 1, 0) -> 1
A9: 394846466 | B9: 972089 | C9: 44393 | D9: Google Ads | E9: =IF(ISNUMBER(MATCH(marketing_events_raw[[#This Row],[customer_id]], customers_clean!A:A, 0)), 1, 0) -> 1
A10: 156160043 | B10: 774079 | C10: 45173 | D10: LinkedIn Ads | E10: =IF(ISNUMBER(MATCH(marketing_events_raw[[#This Row],[customer_id]], customers_clean!A:A, 0)), 1, 0) -> 1
A11: 579329976 | B11: 379766 | C11: 45073 | D11: LinkedIn Ads | E11: =IF(ISNUMBER(MATCH(marketing_events_raw[[#This Row],[customer_id]], customers_clean!A:A, 0)), 1, 0) -> 1
A12: 944923676 | B12: 571980 | C12: 45231 | D12: Partner | E12: =IF(ISNUMBER(MATCH(marketing_events_raw[[#This Row],[customer_id]], customers_clean!A:A, 0)), 1, 0) -> 1
A13: 670108036 | B13: 549622 | C13: 44653 | D13: Referral | E13: =IF(ISNUMBER(MATCH(marketing_events_raw[[#This Row],[customer_id]], customers_clean!A:A, 0)), 1, 0) -> 1
... A1801: 470614696 | B1801: 957266 | C1801: 45653 | D1801: Facebook Ads | E1801: =IF(ISNUMBER(MATCH(marketing_events_raw[[#This Row],[customer_id]], customers_clean!A:A, 0)), 1, 0) -> 1
